 __  __  ___  ____  _____ ____  _   _   _     _______     _______ _     ____  
|  \/  |/ _ \|  _ \| ____|  _ \| \ | | | |   | ____\ \   / / ____| |   / ___| 
| |\/| | | | | | | |  _| | |_) |  \| | | |   |  _|  \ \ / /|  _| | |   \___ \ 
| |  | | |_| | |_| | |___|  _ <| |\  | | |___| |___  \ V / | |___| |___ ___) |
|_|  |_|\___/|____/|_____|_| \_\_| \_| |_____|_____|  \_/  |_____|_____|____/ 
                                                                              

Thank you for downloading Modern Levels 2.0 <3 
If you run into any issues, want to suggest a feature or want a place to hang out, join the Discord! discord.gg/UgvTHmuyNK

Logged In As:
Username: ReputationBot
ID: 1019309208258236416
Database Type: Mongodb
[Status Addon] Addon Started - Bot Description Loaded!
[Extras Addon] Addon Started - Add or Remove XP from users!
[Vocal Addon] Addon Started - Join a VC to earn XP!
Mushroom Laboratroy
Error in 'KumosLab/Database/get.py' - 'NoneType' object is not subscriptable
User Not Found!
Error in 'KumosLab/Database/get.py' - 'NoneType' object is not subscriptable
Error in 'KumosLab/Database/check.py' - '<' not supported between instances of 'NoneType' and 'float'
User Not Found!
Error in 'KumosLab/Database/get.py' - 'NoneType' object is not subscriptable
Error in 'KumosLab/Database/check.py' - '<' not supported between instances of 'NoneType' and 'float'
User Not Found!
Error in 'KumosLab/Database/get.py' - 'NoneType' object is not subscriptable
[Vacefron Rank Card] '<' not supported between instances of 'NoneType' and 'float'
[Rank Command] '<' not supported between instances of 'NoneType' and 'float'
Ignoring exception in on_command_error
Traceback (most recent call last):
  File "/home/pirate/mushroom/Discord-XP-bot/venv/lib/python3.7/site-packages/discord/ext/commands/core.py", line 85, in wrapped
    ret = await coro(*args, **kwargs)
  File "/home/pirate/mushroom/Discord-XP-bot/Commands/rank.py", line 50, in rank
    raise e
  File "/home/pirate/mushroom/Discord-XP-bot/Commands/rank.py", line 41, in rank
    rank = await KumosLab.Database.Create.RankCard.text.generate(user=member, guild=ctx.guild)
  File "/home/pirate/mushroom/Discord-XP-bot/KumosLab/Database/Create/RankCard/text.py", line 65, in generate
    raise e
  File "/home/pirate/mushroom/Discord-XP-bot/KumosLab/Database/Create/RankCard/text.py", line 35, in generate
    if xp < ((config['xp_per_level'] / 2 * (lvl ** 2)) + (config['xp_per_level'] / 2 * lvl)):
TypeError: '<' not supported between instances of 'NoneType' and 'float'

The above exception was the direct cause of the following exception:

Traceback (most recent call last):
  File "/home/pirate/mushroom/Discord-XP-bot/venv/lib/python3.7/site-packages/discord/client.py", line 343, in _run_event
    await coro(*args, **kwargs)
  File "main.py", line 110, in on_command_error
    raise error
  File "/home/pirate/mushroom/Discord-XP-bot/venv/lib/python3.7/site-packages/discord/ext/commands/bot.py", line 939, in invoke
    await ctx.command.invoke(ctx)
  File "/home/pirate/mushroom/Discord-XP-bot/venv/lib/python3.7/site-packages/discord/ext/commands/core.py", line 863, in invoke
    await injected(*ctx.args, **ctx.kwargs)
  File "/home/pirate/mushroom/Discord-XP-bot/venv/lib/python3.7/site-packages/discord/ext/commands/core.py", line 94, in wrapped
    raise CommandInvokeError(exc) from exc
discord.ext.commands.errors.CommandInvokeError: Command raised an exception: TypeError: '<' not supported between instances of 'NoneType' and 'float'
chriswong#1034  ========
victorj#9763  ========
CryptoFox#4210  ========
Ignoring exception in on_member_remove
Traceback (most recent call last):
  File "/home/pirate/mushroom/Discord-XP-bot/venv/lib/python3.7/site-packages/pymongo/mongo_client.py", line 1404, in _retry_internal
    server = self._select_server(writable_server_selector, session)
  File "/home/pirate/mushroom/Discord-XP-bot/venv/lib/python3.7/site-packages/pymongo/mongo_client.py", line 1278, in _select_server
    server = topology.select_server(server_selector)
  File "/home/pirate/mushroom/Discord-XP-bot/venv/lib/python3.7/site-packages/pymongo/topology.py", line 243, in select_server
    address))
  File "/home/pirate/mushroom/Discord-XP-bot/venv/lib/python3.7/site-packages/pymongo/topology.py", line 200, in select_servers
    selector, server_timeout, address)
  File "/home/pirate/mushroom/Discord-XP-bot/venv/lib/python3.7/site-packages/pymongo/topology.py", line 217, in _select_servers_loop
    (self._error_message(selector), timeout, self.description))
pymongo.errors.ServerSelectionTimeoutError: 35.222.63.199:27017: timed out, Timeout: 30s, Topology Description: <TopologyDescription id: 6328d0ed65f4eeb51154b14a, topology_type: Single, servers: [<ServerDescription ('35.222.63.199', 27017) server_type: Unknown, rtt: None, error=NetworkTimeout('35.222.63.199:27017: timed out')>]>

During handling of the above exception, another exception occurred:

Traceback (most recent call last):
  File "/home/pirate/mushroom/Discord-XP-bot/venv/lib/python3.7/site-packages/discord/client.py", line 343, in _run_event
    await coro(*args, **kwargs)
  File "/home/pirate/mushroom/Discord-XP-bot/System/levelsystem.py", line 166, in on_member_remove
    levelling.delete_one({"guild_id": member.guild.id, "user_id": member.id})
  File "/home/pirate/mushroom/Discord-XP-bot/venv/lib/python3.7/site-packages/pymongo/collection.py", line 1242, in delete_one
    collation=collation, hint=hint, session=session),
  File "/home/pirate/mushroom/Discord-XP-bot/venv/lib/python3.7/site-packages/pymongo/collection.py", line 1199, in _delete_retryable
    _delete, session)
  File "/home/pirate/mushroom/Discord-XP-bot/venv/lib/python3.7/site-packages/pymongo/mongo_client.py", line 1498, in _retryable_write
    return self._retry_with_session(retryable, func, s, None)
  File "/home/pirate/mushroom/Discord-XP-bot/venv/lib/python3.7/site-packages/pymongo/mongo_client.py", line 1384, in _retry_with_session
    return self._retry_internal(retryable, func, session, bulk)
  File "/home/pirate/mushroom/Discord-XP-bot/venv/lib/python3.7/site-packages/pymongo/mongo_client.py", line 1422, in _retry_internal
    raise last_error
  File "/home/pirate/mushroom/Discord-XP-bot/venv/lib/python3.7/site-packages/pymongo/mongo_client.py", line 1408, in _retry_internal
    with self._get_socket(server, session) as sock_info:
  File "/usr/lib/python3.7/contextlib.py", line 112, in __enter__
    return next(self.gen)
  File "/home/pirate/mushroom/Discord-XP-bot/venv/lib/python3.7/site-packages/pymongo/mongo_client.py", line 1247, in _get_socket
    self.__all_credentials, checkout=exhaust) as sock_info:
  File "/usr/lib/python3.7/contextlib.py", line 112, in __enter__
    return next(self.gen)
  File "/home/pirate/mushroom/Discord-XP-bot/venv/lib/python3.7/site-packages/pymongo/pool.py", line 1231, in get_socket
    sock_info = self._get_socket(all_credentials)
  File "/home/pirate/mushroom/Discord-XP-bot/venv/lib/python3.7/site-packages/pymongo/pool.py", line 1281, in _get_socket
    sock_info = self.connect(all_credentials)
  File "/home/pirate/mushroom/Discord-XP-bot/venv/lib/python3.7/site-packages/pymongo/pool.py", line 1187, in connect
    _raise_connection_failure(self.address, error)
  File "/home/pirate/mushroom/Discord-XP-bot/venv/lib/python3.7/site-packages/pymongo/pool.py", line 277, in _raise_connection_failure
    raise NetworkTimeout(msg)
pymongo.errors.NetworkTimeout: 35.222.63.199:27017: timed out
Ignoring exception in on_member_join
Traceback (most recent call last):
  File "/home/pirate/mushroom/Discord-XP-bot/venv/lib/python3.7/site-packages/pymongo/mongo_client.py", line 1404, in _retry_internal
    server = self._select_server(writable_server_selector, session)
  File "/home/pirate/mushroom/Discord-XP-bot/venv/lib/python3.7/site-packages/pymongo/mongo_client.py", line 1278, in _select_server
    server = topology.select_server(server_selector)
  File "/home/pirate/mushroom/Discord-XP-bot/venv/lib/python3.7/site-packages/pymongo/topology.py", line 243, in select_server
    address))
  File "/home/pirate/mushroom/Discord-XP-bot/venv/lib/python3.7/site-packages/pymongo/topology.py", line 200, in select_servers
    selector, server_timeout, address)
  File "/home/pirate/mushroom/Discord-XP-bot/venv/lib/python3.7/site-packages/pymongo/topology.py", line 217, in _select_servers_loop
    (self._error_message(selector), timeout, self.description))
pymongo.errors.ServerSelectionTimeoutError: 35.222.63.199:27017: timed out, Timeout: 30s, Topology Description: <TopologyDescription id: 6328d0ed65f4eeb51154b149, topology_type: Single, servers: [<ServerDescription ('35.222.63.199', 27017) server_type: Unknown, rtt: None, error=NetworkTimeout('35.222.63.199:27017: timed out')>]>

During handling of the above exception, another exception occurred:

Traceback (most recent call last):
  File "/home/pirate/mushroom/Discord-XP-bot/venv/lib/python3.7/site-packages/discord/client.py", line 343, in _run_event
    await coro(*args, **kwargs)
  File "/home/pirate/mushroom/Discord-XP-bot/System/levelsystem.py", line 156, in on_member_join
    await KumosLab.Database.insert.userField(member=member, guild=member.guild)
  File "/home/pirate/mushroom/Discord-XP-bot/KumosLab/Database/insert.py", line 24, in userField
    "border": config['Default_Border']})
  File "/home/pirate/mushroom/Discord-XP-bot/venv/lib/python3.7/site-packages/pymongo/collection.py", line 701, in insert_one
    session=session),
  File "/home/pirate/mushroom/Discord-XP-bot/venv/lib/python3.7/site-packages/pymongo/collection.py", line 615, in _insert
    bypass_doc_val, session)
  File "/home/pirate/mushroom/Discord-XP-bot/venv/lib/python3.7/site-packages/pymongo/collection.py", line 603, in _insert_one
    acknowledged, _insert_command, session)
  File "/home/pirate/mushroom/Discord-XP-bot/venv/lib/python3.7/site-packages/pymongo/mongo_client.py", line 1498, in _retryable_write
    return self._retry_with_session(retryable, func, s, None)
  File "/home/pirate/mushroom/Discord-XP-bot/venv/lib/python3.7/site-packages/pymongo/mongo_client.py", line 1384, in _retry_with_session
    return self._retry_internal(retryable, func, session, bulk)
  File "/home/pirate/mushroom/Discord-XP-bot/venv/lib/python3.7/site-packages/pymongo/mongo_client.py", line 1422, in _retry_internal
    raise last_error
  File "/home/pirate/mushroom/Discord-XP-bot/venv/lib/python3.7/site-packages/pymongo/mongo_client.py", line 1408, in _retry_internal
    with self._get_socket(server, session) as sock_info:
  File "/usr/lib/python3.7/contextlib.py", line 112, in __enter__
    return next(self.gen)
  File "/home/pirate/mushroom/Discord-XP-bot/venv/lib/python3.7/site-packages/pymongo/mongo_client.py", line 1247, in _get_socket
    self.__all_credentials, checkout=exhaust) as sock_info:
  File "/usr/lib/python3.7/contextlib.py", line 112, in __enter__
    return next(self.gen)
  File "/home/pirate/mushroom/Discord-XP-bot/venv/lib/python3.7/site-packages/pymongo/pool.py", line 1231, in get_socket
    sock_info = self._get_socket(all_credentials)
  File "/home/pirate/mushroom/Discord-XP-bot/venv/lib/python3.7/site-packages/pymongo/pool.py", line 1281, in _get_socket
    sock_info = self.connect(all_credentials)
  File "/home/pirate/mushroom/Discord-XP-bot/venv/lib/python3.7/site-packages/pymongo/pool.py", line 1187, in connect
    _raise_connection_failure(self.address, error)
  File "/home/pirate/mushroom/Discord-XP-bot/venv/lib/python3.7/site-packages/pymongo/pool.py", line 277, in _raise_connection_failure
    raise NetworkTimeout(msg)
pymongo.errors.NetworkTimeout: 35.222.63.199:27017: timed out
Error in 'KumosLab/Database/get.py' - 35.222.63.199:27017: timed out
Error in 'KumosLab/Database/get.py' - 35.222.63.199:27017: timed out, Timeout: 30s, Topology Description: <TopologyDescription id: 6328d0ec65f4eeb51154b143, topology_type: Single, servers: [<ServerDescription ('35.222.63.199', 27017) server_type: Unknown, rtt: None, error=NetworkTimeout('35.222.63.199:27017: timed out')>]>
Error in 'KumosLab/Database/get.py' - 35.222.63.199:27017: timed out, Timeout: 30s, Topology Description: <TopologyDescription id: 6328d0ec65f4eeb51154b143, topology_type: Single, servers: [<ServerDescription ('35.222.63.199', 27017) server_type: Unknown, rtt: None, error=NetworkTimeout('35.222.63.199:27017: timed out')>]>
[Vacefron Rank Card] '<' not supported between instances of 'NoneType' and 'float'
[Rank Command] '<' not supported between instances of 'NoneType' and 'float'
Ignoring exception in on_command_error
Traceback (most recent call last):
  File "/home/pirate/mushroom/Discord-XP-bot/venv/lib/python3.7/site-packages/discord/ext/commands/core.py", line 85, in wrapped
    ret = await coro(*args, **kwargs)
  File "/home/pirate/mushroom/Discord-XP-bot/Commands/rank.py", line 50, in rank
    raise e
  File "/home/pirate/mushroom/Discord-XP-bot/Commands/rank.py", line 41, in rank
    rank = await KumosLab.Database.Create.RankCard.text.generate(user=member, guild=ctx.guild)
  File "/home/pirate/mushroom/Discord-XP-bot/KumosLab/Database/Create/RankCard/text.py", line 65, in generate
    raise e
  File "/home/pirate/mushroom/Discord-XP-bot/KumosLab/Database/Create/RankCard/text.py", line 35, in generate
    if xp < ((config['xp_per_level'] / 2 * (lvl ** 2)) + (config['xp_per_level'] / 2 * lvl)):
TypeError: '<' not supported between instances of 'NoneType' and 'float'

The above exception was the direct cause of the following exception:

Traceback (most recent call last):
  File "/home/pirate/mushroom/Discord-XP-bot/venv/lib/python3.7/site-packages/discord/client.py", line 343, in _run_event
    await coro(*args, **kwargs)
  File "main.py", line 110, in on_command_error
    raise error
  File "/home/pirate/mushroom/Discord-XP-bot/venv/lib/python3.7/site-packages/discord/ext/commands/bot.py", line 939, in invoke
    await ctx.command.invoke(ctx)
  File "/home/pirate/mushroom/Discord-XP-bot/venv/lib/python3.7/site-packages/discord/ext/commands/core.py", line 863, in invoke
    await injected(*ctx.args, **ctx.kwargs)
  File "/home/pirate/mushroom/Discord-XP-bot/venv/lib/python3.7/site-packages/discord/ext/commands/core.py", line 94, in wrapped
    raise CommandInvokeError(exc) from exc
discord.ext.commands.errors.CommandInvokeError: Command raised an exception: TypeError: '<' not supported between instances of 'NoneType' and 'float'
 __  __  ___  ____  _____ ____  _   _   _     _______     _______ _     ____  
|  \/  |/ _ \|  _ \| ____|  _ \| \ | | | |   | ____\ \   / / ____| |   / ___| 
| |\/| | | | | | | |  _| | |_) |  \| | | |   |  _|  \ \ / /|  _| | |   \___ \ 
| |  | | |_| | |_| | |___|  _ <| |\  | | |___| |___  \ V / | |___| |___ ___) |
|_|  |_|\___/|____/|_____|_| \_\_| \_| |_____|_____|  \_/  |_____|_____|____/ 
                                                                              

Thank you for downloading Modern Levels 2.0 <3 
If you run into any issues, want to suggest a feature or want a place to hang out, join the Discord! discord.gg/UgvTHmuyNK

Logged In As:
Username: ReputationBot
ID: 1019309208258236416
Database Type: Mongodb
[Status Addon] Addon Started - Bot Description Loaded!
[Extras Addon] Addon Started - Add or Remove XP from users!
[Vocal Addon] Addon Started - Join a VC to earn XP!
Ignoring exception in on_ready
Traceback (most recent call last):
  File "/home/pirate/mushroom/Discord-XP-bot/venv/lib/python3.7/site-packages/discord/client.py", line 343, in _run_event
    await coro(*args, **kwargs)
  File "/home/pirate/mushroom/Discord-XP-bot/System/autoupdater.py", line 25, in on_ready
    update.start(self)
  File "/home/pirate/mushroom/Discord-XP-bot/venv/lib/python3.7/site-packages/discord/ext/tasks/__init__.py", line 205, in start
    raise RuntimeError('Task is already launched and is not completed.')
RuntimeError: Task is already launched and is not completed.
CryptoFox#4210  ========
Ignoring exception in on_member_remove
Traceback (most recent call last):
  File "/home/pirate/mushroom/Discord-XP-bot/venv/lib/python3.7/site-packages/discord/client.py", line 343, in _run_event
    await coro(*args, **kwargs)
  File "/home/pirate/mushroom/Discord-XP-bot/System/levelsystem.py", line 166, in on_member_remove
    levelling.delete_one({"guild_id": member.guild.id, "user_id": member.id})
  File "/home/pirate/mushroom/Discord-XP-bot/venv/lib/python3.7/site-packages/pymongo/collection.py", line 1242, in delete_one
    collation=collation, hint=hint, session=session),
  File "/home/pirate/mushroom/Discord-XP-bot/venv/lib/python3.7/site-packages/pymongo/collection.py", line 1199, in _delete_retryable
    _delete, session)
  File "/home/pirate/mushroom/Discord-XP-bot/venv/lib/python3.7/site-packages/pymongo/mongo_client.py", line 1497, in _retryable_write
    with self._tmp_session(session) as s:
  File "/usr/lib/python3.7/contextlib.py", line 112, in __enter__
    return next(self.gen)
  File "/home/pirate/mushroom/Discord-XP-bot/venv/lib/python3.7/site-packages/pymongo/mongo_client.py", line 1829, in _tmp_session
    s = self._ensure_session(session)
  File "/home/pirate/mushroom/Discord-XP-bot/venv/lib/python3.7/site-packages/pymongo/mongo_client.py", line 1816, in _ensure_session
    return self.__start_session(True, causal_consistency=False)
  File "/home/pirate/mushroom/Discord-XP-bot/venv/lib/python3.7/site-packages/pymongo/mongo_client.py", line 1766, in __start_session
    server_session = self._get_server_session()
  File "/home/pirate/mushroom/Discord-XP-bot/venv/lib/python3.7/site-packages/pymongo/mongo_client.py", line 1802, in _get_server_session
    return self._topology.get_server_session()
  File "/home/pirate/mushroom/Discord-XP-bot/venv/lib/python3.7/site-packages/pymongo/topology.py", line 499, in get_server_session
    None)
  File "/home/pirate/mushroom/Discord-XP-bot/venv/lib/python3.7/site-packages/pymongo/topology.py", line 217, in _select_servers_loop
    (self._error_message(selector), timeout, self.description))
pymongo.errors.ServerSelectionTimeoutError: 35.222.63.199:27017: timed out, Timeout: 30s, Topology Description: <TopologyDescription id: 6328d0ed65f4eeb51154b14a, topology_type: Single, servers: [<ServerDescription ('35.222.63.199', 27017) server_type: Unknown, rtt: None, error=NetworkTimeout('35.222.63.199:27017: timed out')>]>
Ignoring exception in on_member_join
Traceback (most recent call last):
  File "/home/pirate/mushroom/Discord-XP-bot/venv/lib/python3.7/site-packages/discord/client.py", line 343, in _run_event
    await coro(*args, **kwargs)
  File "/home/pirate/mushroom/Discord-XP-bot/System/levelsystem.py", line 156, in on_member_join
    await KumosLab.Database.insert.userField(member=member, guild=member.guild)
  File "/home/pirate/mushroom/Discord-XP-bot/KumosLab/Database/insert.py", line 24, in userField
    "border": config['Default_Border']})
  File "/home/pirate/mushroom/Discord-XP-bot/venv/lib/python3.7/site-packages/pymongo/collection.py", line 701, in insert_one
    session=session),
  File "/home/pirate/mushroom/Discord-XP-bot/venv/lib/python3.7/site-packages/pymongo/collection.py", line 615, in _insert
    bypass_doc_val, session)
  File "/home/pirate/mushroom/Discord-XP-bot/venv/lib/python3.7/site-packages/pymongo/collection.py", line 603, in _insert_one
    acknowledged, _insert_command, session)
  File "/home/pirate/mushroom/Discord-XP-bot/venv/lib/python3.7/site-packages/pymongo/mongo_client.py", line 1497, in _retryable_write
    with self._tmp_session(session) as s:
  File "/usr/lib/python3.7/contextlib.py", line 112, in __enter__
    return next(self.gen)
  File "/home/pirate/mushroom/Discord-XP-bot/venv/lib/python3.7/site-packages/pymongo/mongo_client.py", line 1829, in _tmp_session
    s = self._ensure_session(session)
  File "/home/pirate/mushroom/Discord-XP-bot/venv/lib/python3.7/site-packages/pymongo/mongo_client.py", line 1816, in _ensure_session
    return self.__start_session(True, causal_consistency=False)
  File "/home/pirate/mushroom/Discord-XP-bot/venv/lib/python3.7/site-packages/pymongo/mongo_client.py", line 1766, in __start_session
    server_session = self._get_server_session()
  File "/home/pirate/mushroom/Discord-XP-bot/venv/lib/python3.7/site-packages/pymongo/mongo_client.py", line 1802, in _get_server_session
    return self._topology.get_server_session()
  File "/home/pirate/mushroom/Discord-XP-bot/venv/lib/python3.7/site-packages/pymongo/topology.py", line 499, in get_server_session
    None)
  File "/home/pirate/mushroom/Discord-XP-bot/venv/lib/python3.7/site-packages/pymongo/topology.py", line 217, in _select_servers_loop
    (self._error_message(selector), timeout, self.description))
pymongo.errors.ServerSelectionTimeoutError: 35.222.63.199:27017: timed out, Timeout: 30s, Topology Description: <TopologyDescription id: 6328d0ed65f4eeb51154b149, topology_type: Single, servers: [<ServerDescription ('35.222.63.199', 27017) server_type: Unknown, rtt: None, error=NetworkTimeout('35.222.63.199:27017: timed out')>]>
Error in 'KumosLab/Database/get.py' - 35.222.63.199:27017: timed out, Timeout: 30s, Topology Description: <TopologyDescription id: 6328d0ec65f4eeb51154b143, topology_type: Single, servers: [<ServerDescription ('35.222.63.199', 27017) server_type: Unknown, rtt: None, error=NetworkTimeout('35.222.63.199:27017: timed out')>]>
Error in 'KumosLab/Database/get.py' - 35.222.63.199:27017: timed out, Timeout: 30s, Topology Description: <TopologyDescription id: 6328d0ec65f4eeb51154b143, topology_type: Single, servers: [<ServerDescription ('35.222.63.199', 27017) server_type: Unknown, rtt: None, error=NetworkTimeout('35.222.63.199:27017: timed out')>]>
Error in 'KumosLab/Database/get.py' - 35.222.63.199:27017: timed out, Timeout: 30s, Topology Description: <TopologyDescription id: 6328d0ec65f4eeb51154b143, topology_type: Single, servers: [<ServerDescription ('35.222.63.199', 27017) server_type: Unknown, rtt: None, error=NetworkTimeout('35.222.63.199:27017: timed out')>]>
[Vacefron Rank Card] '<' not supported between instances of 'NoneType' and 'float'
[Rank Command] '<' not supported between instances of 'NoneType' and 'float'
Ignoring exception in on_command_error
Traceback (most recent call last):
  File "/home/pirate/mushroom/Discord-XP-bot/venv/lib/python3.7/site-packages/discord/ext/commands/core.py", line 85, in wrapped
    ret = await coro(*args, **kwargs)
  File "/home/pirate/mushroom/Discord-XP-bot/Commands/rank.py", line 50, in rank
    raise e
  File "/home/pirate/mushroom/Discord-XP-bot/Commands/rank.py", line 41, in rank
    rank = await KumosLab.Database.Create.RankCard.text.generate(user=member, guild=ctx.guild)
  File "/home/pirate/mushroom/Discord-XP-bot/KumosLab/Database/Create/RankCard/text.py", line 65, in generate
    raise e
  File "/home/pirate/mushroom/Discord-XP-bot/KumosLab/Database/Create/RankCard/text.py", line 35, in generate
    if xp < ((config['xp_per_level'] / 2 * (lvl ** 2)) + (config['xp_per_level'] / 2 * lvl)):
TypeError: '<' not supported between instances of 'NoneType' and 'float'

The above exception was the direct cause of the following exception:

Traceback (most recent call last):
  File "/home/pirate/mushroom/Discord-XP-bot/venv/lib/python3.7/site-packages/discord/client.py", line 343, in _run_event
    await coro(*args, **kwargs)
  File "main.py", line 110, in on_command_error
    raise error
  File "/home/pirate/mushroom/Discord-XP-bot/venv/lib/python3.7/site-packages/discord/ext/commands/bot.py", line 939, in invoke
    await ctx.command.invoke(ctx)
  File "/home/pirate/mushroom/Discord-XP-bot/venv/lib/python3.7/site-packages/discord/ext/commands/core.py", line 863, in invoke
    await injected(*ctx.args, **ctx.kwargs)
  File "/home/pirate/mushroom/Discord-XP-bot/venv/lib/python3.7/site-packages/discord/ext/commands/core.py", line 94, in wrapped
    raise CommandInvokeError(exc) from exc
discord.ext.commands.errors.CommandInvokeError: Command raised an exception: TypeError: '<' not supported between instances of 'NoneType' and 'float'
 __  __  ___  ____  _____ ____  _   _   _     _______     _______ _     ____  
|  \/  |/ _ \|  _ \| ____|  _ \| \ | | | |   | ____\ \   / / ____| |   / ___| 
| |\/| | | | | | | |  _| | |_) |  \| | | |   |  _|  \ \ / /|  _| | |   \___ \ 
| |  | | |_| | |_| | |___|  _ <| |\  | | |___| |___  \ V / | |___| |___ ___) |
|_|  |_|\___/|____/|_____|_| \_\_| \_| |_____|_____|  \_/  |_____|_____|____/ 
                                                                              

Thank you for downloading Modern Levels 2.0 <3 
If you run into any issues, want to suggest a feature or want a place to hang out, join the Discord! discord.gg/UgvTHmuyNK

Logged In As:
Username: ReputationBot
ID: 1019309208258236416
Database Type: Mongodb
[Status Addon] Addon Started - Bot Description Loaded!
[Extras Addon] Addon Started - Add or Remove XP from users!
[Vocal Addon] Addon Started - Join a VC to earn XP!
Ignoring exception in on_ready
Traceback (most recent call last):
  File "/home/pirate/mushroom/Discord-XP-bot/venv/lib/python3.7/site-packages/discord/client.py", line 343, in _run_event
    await coro(*args, **kwargs)
  File "/home/pirate/mushroom/Discord-XP-bot/System/autoupdater.py", line 25, in on_ready
    update.start(self)
  File "/home/pirate/mushroom/Discord-XP-bot/venv/lib/python3.7/site-packages/discord/ext/tasks/__init__.py", line 205, in start
    raise RuntimeError('Task is already launched and is not completed.')
RuntimeError: Task is already launched and is not completed.
Error in 'KumosLab/Database/get.py' - 35.222.63.199:27017: timed out, Timeout: 30s, Topology Description: <TopologyDescription id: 6328d0ec65f4eeb51154b143, topology_type: Single, servers: [<ServerDescription ('35.222.63.199', 27017) server_type: Unknown, rtt: None, error=NetworkTimeout('35.222.63.199:27017: timed out')>]>
Error in 'KumosLab/Database/get.py' - 35.222.63.199:27017: timed out, Timeout: 30s, Topology Description: <TopologyDescription id: 6328d0ec65f4eeb51154b143, topology_type: Single, servers: [<ServerDescription ('35.222.63.199', 27017) server_type: Unknown, rtt: None, error=NetworkTimeout('35.222.63.199:27017: timed out')>]>
Error in 'KumosLab/Database/get.py' - 'NoneType' object is not subscriptable
[Vacefron Rank Card] '<' not supported between instances of 'NoneType' and 'float'
[Rank Command] '<' not supported between instances of 'NoneType' and 'float'
Error in 'KumosLab/Database/get.py' - 'NoneType' object is not subscriptable
User Not Found!
Error in 'KumosLab/Database/get.py' - 'NoneType' object is not subscriptable
[Vacefron Rank Card] '<' not supported between instances of 'NoneType' and 'float'
[Rank Command] '<' not supported between instances of 'NoneType' and 'float'
CryptoFox#4210  ========
CryptoFox#4210  ========
Ignoring exception in on_command_error
Traceback (most recent call last):
  File "/home/pirate/mushroom/Discord-XP-bot/venv/lib/python3.7/site-packages/discord/ext/commands/core.py", line 85, in wrapped
    ret = await coro(*args, **kwargs)
  File "/home/pirate/mushroom/Discord-XP-bot/Commands/rank.py", line 50, in rank
    raise e
  File "/home/pirate/mushroom/Discord-XP-bot/Commands/rank.py", line 41, in rank
    rank = await KumosLab.Database.Create.RankCard.text.generate(user=member, guild=ctx.guild)
  File "/home/pirate/mushroom/Discord-XP-bot/KumosLab/Database/Create/RankCard/text.py", line 65, in generate
    raise e
  File "/home/pirate/mushroom/Discord-XP-bot/KumosLab/Database/Create/RankCard/text.py", line 35, in generate
    if xp < ((config['xp_per_level'] / 2 * (lvl ** 2)) + (config['xp_per_level'] / 2 * lvl)):
TypeError: '<' not supported between instances of 'NoneType' and 'float'

The above exception was the direct cause of the following exception:

Traceback (most recent call last):
  File "/home/pirate/mushroom/Discord-XP-bot/venv/lib/python3.7/site-packages/discord/client.py", line 343, in _run_event
    await coro(*args, **kwargs)
  File "main.py", line 110, in on_command_error
    raise error
  File "/home/pirate/mushroom/Discord-XP-bot/venv/lib/python3.7/site-packages/discord/ext/commands/bot.py", line 939, in invoke
    await ctx.command.invoke(ctx)
  File "/home/pirate/mushroom/Discord-XP-bot/venv/lib/python3.7/site-packages/discord/ext/commands/core.py", line 863, in invoke
    await injected(*ctx.args, **ctx.kwargs)
  File "/home/pirate/mushroom/Discord-XP-bot/venv/lib/python3.7/site-packages/discord/ext/commands/core.py", line 94, in wrapped
    raise CommandInvokeError(exc) from exc
discord.ext.commands.errors.CommandInvokeError: Command raised an exception: TypeError: '<' not supported between instances of 'NoneType' and 'float'
Ignoring exception in on_command_error
Traceback (most recent call last):
  File "/home/pirate/mushroom/Discord-XP-bot/venv/lib/python3.7/site-packages/discord/ext/commands/core.py", line 85, in wrapped
    ret = await coro(*args, **kwargs)
  File "/home/pirate/mushroom/Discord-XP-bot/Commands/rank.py", line 50, in rank
    raise e
  File "/home/pirate/mushroom/Discord-XP-bot/Commands/rank.py", line 41, in rank
    rank = await KumosLab.Database.Create.RankCard.text.generate(user=member, guild=ctx.guild)
  File "/home/pirate/mushroom/Discord-XP-bot/KumosLab/Database/Create/RankCard/text.py", line 65, in generate
    raise e
  File "/home/pirate/mushroom/Discord-XP-bot/KumosLab/Database/Create/RankCard/text.py", line 35, in generate
    if xp < ((config['xp_per_level'] / 2 * (lvl ** 2)) + (config['xp_per_level'] / 2 * lvl)):
TypeError: '<' not supported between instances of 'NoneType' and 'float'

The above exception was the direct cause of the following exception:

Traceback (most recent call last):
  File "/home/pirate/mushroom/Discord-XP-bot/venv/lib/python3.7/site-packages/discord/client.py", line 343, in _run_event
    await coro(*args, **kwargs)
  File "main.py", line 110, in on_command_error
    raise error
  File "/home/pirate/mushroom/Discord-XP-bot/venv/lib/python3.7/site-packages/discord/ext/commands/bot.py", line 939, in invoke
    await ctx.command.invoke(ctx)
  File "/home/pirate/mushroom/Discord-XP-bot/venv/lib/python3.7/site-packages/discord/ext/commands/core.py", line 863, in invoke
    await injected(*ctx.args, **ctx.kwargs)
  File "/home/pirate/mushroom/Discord-XP-bot/venv/lib/python3.7/site-packages/discord/ext/commands/core.py", line 94, in wrapped
    raise CommandInvokeError(exc) from exc
discord.ext.commands.errors.CommandInvokeError: Command raised an exception: TypeError: '<' not supported between instances of 'NoneType' and 'float'
Server Not Found!
Ignoring exception in on_message
Traceback (most recent call last):
  File "/home/pirate/mushroom/Discord-XP-bot/venv/lib/python3.7/site-packages/discord/client.py", line 343, in _run_event
    await coro(*args, **kwargs)
  File "/home/pirate/mushroom/Discord-XP-bot/System/levelsystem.py", line 55, in on_message
    for channel in channels:
TypeError: 'NoneType' object is not iterable
Ignoring exception in on_command_error
Traceback (most recent call last):
  File "/home/pirate/mushroom/Discord-XP-bot/venv/lib/python3.7/site-packages/discord/client.py", line 343, in _run_event
    await coro(*args, **kwargs)
  File "main.py", line 110, in on_command_error
    raise error
  File "/home/pirate/mushroom/Discord-XP-bot/venv/lib/python3.7/site-packages/discord/ext/commands/bot.py", line 939, in invoke
    await ctx.command.invoke(ctx)
  File "/home/pirate/mushroom/Discord-XP-bot/venv/lib/python3.7/site-packages/discord/ext/commands/core.py", line 855, in invoke
    await self.prepare(ctx)
  File "/home/pirate/mushroom/Discord-XP-bot/venv/lib/python3.7/site-packages/discord/ext/commands/core.py", line 777, in prepare
    if not await self.can_run(ctx):
  File "/home/pirate/mushroom/Discord-XP-bot/venv/lib/python3.7/site-packages/discord/ext/commands/core.py", line 1087, in can_run
    return await discord.utils.async_all(predicate(ctx) for predicate in predicates)
  File "/home/pirate/mushroom/Discord-XP-bot/venv/lib/python3.7/site-packages/discord/utils.py", line 348, in async_all
    for elem in gen:
  File "/home/pirate/mushroom/Discord-XP-bot/venv/lib/python3.7/site-packages/discord/ext/commands/core.py", line 1087, in <genexpr>
    return await discord.utils.async_all(predicate(ctx) for predicate in predicates)
  File "/home/pirate/mushroom/Discord-XP-bot/venv/lib/python3.7/site-packages/discord/ext/commands/core.py", line 1790, in predicate
    raise MissingPermissions(missing)
discord.ext.commands.errors.MissingPermissions: You are missing Administrator permission(s) to run this command.
Ignoring exception in on_command_error
Traceback (most recent call last):
  File "/home/pirate/mushroom/Discord-XP-bot/venv/lib/python3.7/site-packages/discord/client.py", line 343, in _run_event
    await coro(*args, **kwargs)
  File "main.py", line 110, in on_command_error
    raise error
  File "/home/pirate/mushroom/Discord-XP-bot/venv/lib/python3.7/site-packages/discord/ext/commands/bot.py", line 939, in invoke
    await ctx.command.invoke(ctx)
  File "/home/pirate/mushroom/Discord-XP-bot/venv/lib/python3.7/site-packages/discord/ext/commands/core.py", line 855, in invoke
    await self.prepare(ctx)
  File "/home/pirate/mushroom/Discord-XP-bot/venv/lib/python3.7/site-packages/discord/ext/commands/core.py", line 777, in prepare
    if not await self.can_run(ctx):
  File "/home/pirate/mushroom/Discord-XP-bot/venv/lib/python3.7/site-packages/discord/ext/commands/core.py", line 1087, in can_run
    return await discord.utils.async_all(predicate(ctx) for predicate in predicates)
  File "/home/pirate/mushroom/Discord-XP-bot/venv/lib/python3.7/site-packages/discord/utils.py", line 348, in async_all
    for elem in gen:
  File "/home/pirate/mushroom/Discord-XP-bot/venv/lib/python3.7/site-packages/discord/ext/commands/core.py", line 1087, in <genexpr>
    return await discord.utils.async_all(predicate(ctx) for predicate in predicates)
  File "/home/pirate/mushroom/Discord-XP-bot/venv/lib/python3.7/site-packages/discord/ext/commands/core.py", line 1790, in predicate
    raise MissingPermissions(missing)
discord.ext.commands.errors.MissingPermissions: You are missing Administrator permission(s) to run this command.
 __  __  ___  ____  _____ ____  _   _   _     _______     _______ _     ____  
|  \/  |/ _ \|  _ \| ____|  _ \| \ | | | |   | ____\ \   / / ____| |   / ___| 
| |\/| | | | | | | |  _| | |_) |  \| | | |   |  _|  \ \ / /|  _| | |   \___ \ 
| |  | | |_| | |_| | |___|  _ <| |\  | | |___| |___  \ V / | |___| |___ ___) |
|_|  |_|\___/|____/|_____|_| \_\_| \_| |_____|_____|  \_/  |_____|_____|____/ 
                                                                              

Thank you for downloading Modern Levels 2.0 <3 
If you run into any issues, want to suggest a feature or want a place to hang out, join the Discord! discord.gg/UgvTHmuyNK

Logged In As:
Username: ReputationBot
ID: 1019309208258236416
Database Type: Mongodb
[Status Addon] Addon Started - Bot Description Loaded!
[Extras Addon] Addon Started - Add or Remove XP from users!
[Vocal Addon] Addon Started - Join a VC to earn XP!
Ignoring exception in on_ready
Traceback (most recent call last):
  File "/home/pirate/mushroom/Discord-XP-bot/venv/lib/python3.7/site-packages/discord/client.py", line 343, in _run_event
    await coro(*args, **kwargs)
  File "/home/pirate/mushroom/Discord-XP-bot/System/autoupdater.py", line 25, in on_ready
    update.start(self)
  File "/home/pirate/mushroom/Discord-XP-bot/venv/lib/python3.7/site-packages/discord/ext/tasks/__init__.py", line 205, in start
    raise RuntimeError('Task is already launched and is not completed.')
RuntimeError: Task is already launched and is not completed.
